<?xml version="1.0" ?>
<robot xmlns:xacro="http://www.ros.org/wiki/xacro"
       name="igus_robolink_rl_dp_5" >
  <xacro:macro name="igus_robolink_rl_dp_5_description" params="prefix continuous_last_joint">
    <link name="${prefix}base_link">
      <visual>
        <geometry>
          <mesh filename="file://$(find irc_ros_description)/meshes/igus_robolink_rl_dp_5/Joint0.dae"/>
        </geometry>
      </visual>
      <collision>
        <geometry>
          <mesh filename="file://$(find irc_ros_description)/meshes/igus_robolink_rl_dp_5/Joint0Coll.dae"/>
        </geometry>
      </collision>
      <inertial>
        <mass value="1.0"/>
        <inertia ixx="1.0" ixy="0.0" ixz="0.0" iyy="1.0" iyz="0.0" izz="1.0"/>
      </inertial>
    </link>
    <joint name="${prefix}joint1" type="revolute">
      <parent link="${prefix}base_link"/>
      <child link="${prefix}link_1"/>
      <origin rpy="0.0 0.0 0.0" xyz="0.0 0 0.0095"/>
      <axis xyz="0 0 -1"/>
      <limit effort="330.0" lower="${-pi*7/9}" upper="${pi*7/9}" velocity="2.16"/>
    </joint>
    <link name="${prefix}link_1">
      <visual>
        <geometry>
          <mesh filename="file://$(find irc_ros_description)/meshes/igus_robolink_rl_dp_5/Joint1.dae"/>
        </geometry>
        <origin rpy="0 0 0" xyz="0 0 0"/>
      </visual>
      <collision>
        <geometry>
          <mesh filename="file://$(find irc_ros_description)/meshes/igus_robolink_rl_dp_5/Joint1Coll.dae"/>
        </geometry>
        <origin rpy="0 0 0" xyz="0 0 0"/>
      </collision>
      <inertial>
        <mass value="0.1"/>
        <inertia ixx="0.03" ixy="0.0" ixz="0.0" iyy="0.03" iyz="0.0" izz="0.03"/>
      </inertial>
    </link>
    <joint name="${prefix}joint2" type="revolute">
      <parent link="${prefix}link_1"/>
      <child link="${prefix}link_2"/>
      <origin rpy="0.0 0.0 0.0" xyz="0.0 0 0.145"/>
      <axis xyz="0 1 0"/>
      <limit effort="330.0" lower="${-pi*5/18}" upper="${pi/2}" velocity="2.16"/>
    </joint>
    <link name="${prefix}link_2">
      <visual>
        <geometry>
          <mesh filename="file://$(find irc_ros_description)/meshes/igus_robolink_rl_dp_5/Joint2.dae"/>
        </geometry>
        <origin rpy="0 0 0" xyz="0 0 0"/>
      </visual>
      <collision>
        <geometry>
          <mesh filename="file://$(find irc_ros_description)/meshes/igus_robolink_rl_dp_5/Joint2Coll.dae"/>
        </geometry>
        <origin rpy="0 0 0" xyz="0 0 0"/>
      </collision>
      <inertial>
        <mass value="0.1"/>
        <inertia ixx="0.03" ixy="0.0" ixz="0.0" iyy="0.03" iyz="0.0" izz="0.03"/>
      </inertial>
    </link>
    <joint name="${prefix}joint3" type="revolute">
      <parent link="${prefix}link_2"/>
      <child link="${prefix}link_5"/>
      <origin rpy="0.0 1.57 0.0" xyz="0.0 0.0 0.350"/>
      <axis xyz="0 1 0"/>
      <limit effort="330.0" lower="${-pi*41/36}" upper="${pi*5/36}" velocity="2.16"/>
    </joint>
    <link name="${prefix}link_5">
      <visual>
        <geometry>
          <mesh filename="file://$(find irc_ros_description)/meshes/igus_robolink_rl_dp_5/Joint3.dae"/>
        </geometry>
        <origin rpy="0 0 0" xyz="0 0 0"/>
      </visual>
      <collision>
        <geometry>
          <mesh filename="file://$(find irc_ros_description)/meshes/igus_robolink_rl_dp_5/Joint3Coll.dae"/>
        </geometry>
        <origin rpy="0 0 0" xyz="0 0 0"/>
      </collision>
      <inertial>
        <mass value="0.1"/>
        <inertia ixx="0.03" ixy="0.0" ixz="0.0" iyy="0.03" iyz="0.0" izz="0.03"/>
      </inertial>
    </link>
    <joint name="${prefix}joint4" type="revolute">
      <parent link="${prefix}link_5"/>
      <child link="${prefix}link_6"/>
      <origin rpy="0.0 0.0 0.0" xyz="0.0 0 0.270"/>
      <axis xyz="0 1 0"/>
      <limit effort="330.0" lower="${-pi*5/9}" upper="${pi*5/9}" velocity="2.16"/>
    </joint>
    <link name="${prefix}link_6">
      <visual>
        <geometry>
          <mesh filename="file://$(find irc_ros_description)/meshes/igus_robolink_rl_dp_5/Joint4.dae"/>
        </geometry>
        <origin rpy="0 0 0" xyz="0 0 0"/>
      </visual>
      <collision>
        <geometry>
          <mesh filename="file://$(find irc_ros_description)/meshes/igus_robolink_rl_dp_5/Joint4Coll.dae"/>
        </geometry>
        <origin rpy="0 0 0" xyz="0 0 0"/>
      </collision>
      <inertial>
        <mass value="0.1"/>
        <inertia ixx="0.03" ixy="0.0" ixz="0.0" iyy="0.03" iyz="0.0" izz="0.03"/>
      </inertial>
    </link>
    <xacro:if value="${continuous_last_joint}">
      <joint name="${prefix}joint5" type="continuous">
        <parent link="${prefix}link_6"/>
        <child link="${prefix}link_7"/>
        <origin rpy="0.0 0.0 0.0" xyz="0.0 0 0.1785"/>
        <axis xyz="0 0 1"/>
        <limit effort="330.0" velocity="2.16"/>
      </joint>
    </xacro:if>
    <xacro:unless value="${continuous_last_joint}">
      <joint name="${prefix}joint5" type="revolute">
        <parent link="${prefix}link_6"/>
        <child link="${prefix}link_7"/>
        <origin rpy="0.0 0.0 0.0" xyz="0.0 0 0.1785"/>
        <axis xyz="0 0 1"/>
        <limit effort="330.0" lower="${-pi*179/180}" upper="${pi*179/180}" velocity="2.16"/>
      </joint>
    </xacro:unless>
    <link name="${prefix}link_7">
      <visual>
        <geometry>
          <mesh filename="file://$(find irc_ros_description)/meshes/igus_robolink_rl_dp_5/Joint5.dae"/>
        </geometry>
        <origin rpy="0 0 0" xyz="0 0 0"/>
      </visual>
      <collision>
        <geometry>
          <mesh filename="file://$(find irc_ros_description)/meshes/igus_robolink_rl_dp_5/Joint5Coll.dae"/>
        </geometry>
        <origin rpy="0 0 0" xyz="0 0 0"/>
      </collision>
      <inertial>
        <mass value="0.1"/>
        <inertia ixx="0.03" ixy="0.0" ixz="0.0" iyy="0.03" iyz="0.0" izz="0.03"/>
      </inertial>
    </link>
    <joint name="${prefix}joint6" type="fixed">
      <parent link="${prefix}link_7"/>
      <child link="${prefix}flange"/>
      <origin rpy="0.0 ${-pi/2} 0.0" xyz="0.0 0 0.0115"/>
      <axis xyz="0 0 1"/>
      <limit effort="330.0" lower="-1.65806" upper="1.65806" velocity="2.16"/>
    </joint>
    <link name="${prefix}flange">
    </link>
    <joint name="${prefix}flange_to_tool0" type="fixed">
      <parent link="${prefix}flange"/>
      <child link="${prefix}tool0"/>
      <origin rpy="0.0 0.0 0.0" xyz="0.0 0.0 0.0"/>
      <axis xyz="0 0 0"/>
    </joint>
    <link name="${prefix}tool0">
    </link>
  </xacro:macro>
</robot>
