<?xml version="1.0" ?>
<robot xmlns:xacro="http://www.ros.org/wiki/xacro"
       name="igus_rebel_4dof" >
  <xacro:macro name="igus_rebel_4dof_00_description" params="prefix continuous_last_joint">
    <link name="${prefix}base_link">
      <visual>
        <geometry>
          <mesh filename="file://$(find irc_ros_description)/meshes/igus_rebel_4dof_00/Joint0.dae"/>
        </geometry>
      </visual>
      <collision>
        <geometry>
          <mesh filename="file://$(find irc_ros_description)/meshes/igus_rebel_4dof_00/Joint0Coll.dae"/>
        </geometry>
      </collision>
      <inertial>
        <mass value="1.0"/>
        <inertia ixx="1.0" ixy="0.0" ixz="0.0" iyy="1.0" iyz="0.0" izz="1.0"/>
      </inertial>
    </link>
    <joint name="${prefix}joint1" type="revolute">
      <parent link="${prefix}base_link"/>
      <child link="${prefix}link_1"/>
      <origin rpy="0.0 0.0 0.0" xyz="0.0 0.0 0.100"/>
      <axis xyz="0 0 -1"/>
      <limit effort="330.0" lower="${-pi*179/180}" upper="${pi*179/180}" velocity="${pi*45/180}"/>
    </joint>
    <link name="${prefix}link_1">
      <visual>
        <geometry>
          <mesh filename="file://$(find irc_ros_description)/meshes/igus_rebel_4dof_00/Joint1.dae"/>
        </geometry>
        <origin rpy="0 0 0" xyz="0.0 0.0 0"/>
      </visual>
      <collision>
        <geometry>
          <mesh filename="file://$(find irc_ros_description)/meshes/igus_rebel_4dof_00/Joint1Coll.dae"/>
        </geometry>
        <origin rpy="0 0 0" xyz="0.0 0.0 0"/>
      </collision>
      <inertial>
        <mass value="0.1"/>
        <inertia ixx="0.03" ixy="0.0" ixz="0.0" iyy="0.03" iyz="0.0" izz="0.03"/>
      </inertial>
    </link>
    <joint name="${prefix}joint2" type="revolute">
      <parent link="${prefix}link_1"/>
      <child link="${prefix}link_2"/>
      <origin rpy="0.0 ${pi/6} 0.0" xyz="0.0 0 0.149"/>
      <axis xyz="0 1 0"/>
      <!-- pi*2/3 are the physical limits, but to avoid any collisions we set the actual limits lower -->
      <limit effort="330.0" lower="${-pi*11/18}" upper="${pi*11/18}" velocity="${pi*45/180}"/>
    </joint>
    <link name="${prefix}link_2">
      <visual>
        <geometry>
          <mesh filename="file://$(find irc_ros_description)/meshes/igus_rebel_4dof_00/Joint2.dae"/>
        </geometry>
        <origin rpy="0 0 0" xyz="0 0 0"/>
      </visual>
      <collision>
        <geometry>
          <mesh filename="file://$(find irc_ros_description)/meshes/igus_rebel_4dof_00/Joint2Coll.dae"/>
        </geometry>
        <origin rpy="0 0 0" xyz="0 0 0"/>
      </collision>
      <inertial>
        <mass value="0.1"/>
        <inertia ixx="0.03" ixy="0.0" ixz="0.0" iyy="0.03" iyz="0.0" izz="0.03"/>
      </inertial>
    </link>
    <joint name="${prefix}joint3" type="revolute">
      <parent link="${prefix}link_2"/>
      <child link="${prefix}link_3"/>
      <origin rpy="0.0 ${pi/6} 0.0" xyz="0.0 0.0 0.2384"/> 
      <axis xyz="0 1 0"/>
      <!-- pi*2/3 are the physical limits, but to avoid any collisions we set the actual limits lower -->
      <limit effort="330.0" lower="${-pi*11/18}" upper="${pi*11/18}" velocity="${pi*45/180}"/>
    </joint>
    <link name="${prefix}link_3">
      <visual>
        <geometry>
          <mesh filename="file://$(find irc_ros_description)/meshes/igus_rebel_4dof_00/Joint3.dae"/>
        </geometry>
        <origin rpy="0 0 0" xyz="0 0 0"/>
      </visual>
      <collision>
        <geometry>
          <mesh filename="file://$(find irc_ros_description)/meshes/igus_rebel_4dof_00/Joint3Coll.dae"/>
        </geometry>
        <origin rpy="0 0 0" xyz="0 0 0"/>
      </collision>
      <inertial>
        <mass value="0.1"/>
        <inertia ixx="0.03" ixy="0.0" ixz="0.0" iyy="0.03" iyz="0.0" izz="0.03"/>
      </inertial>
    </link>
    <xacro:if value="${continuous_last_joint}">
      <joint name="${prefix}joint4" type="continuous">
        <parent link="${prefix}link_3"/>
        <child link="${prefix}link_4"/>
        <origin rpy="0.0 ${-pi/24} 0.0" xyz="0.0 0.0 0.2423"/>
        <axis xyz="0 -1 0"/>
        <limit effort="330.0" velocity="2.16"/>
      </joint>
    </xacro:if>
    <xacro:unless value="${continuous_last_joint}">
      <joint name="${prefix}joint4" type="revolute">
        <parent link="${prefix}link_3"/>
        <child link="${prefix}link_4"/>
        <origin rpy="0.0 ${-pi/24} 0.0" xyz="0.0 0.0 0.2423"/>
        <axis xyz="0 1 0"/>
      <limit effort="330.0" lower="${-pi*19/36 + pi/24}" upper="${pi*19/36 + pi/24}" velocity="${pi*45/180}"/>
      </joint>
    </xacro:unless>
    <link name="${prefix}link_4">
      <visual>
        <geometry>
          <mesh filename="file://$(find irc_ros_description)/meshes/igus_rebel_4dof_00/Joint4.dae"/>
        </geometry>
        <origin rpy="0 0 0" xyz="0 0 0"/>
      </visual>
      <collision>
        <geometry>
          <mesh filename="file://$(find irc_ros_description)/meshes/igus_rebel_4dof_00/Joint4Coll.dae"/>
        </geometry>
        <origin rpy="0 0 0" xyz="0 0 0"/>
      </collision>
      <inertial>
        <mass value="0.1"/>
        <inertia ixx="0.03" ixy="0.0" ixz="0.0" iyy="0.03" iyz="0.0" izz="0.03"/>
      </inertial>
    </link>
    <joint name="${prefix}joint5" type="fixed">
      <parent link="${prefix}link_4"/>
      <child link="${prefix}flange"/>
      <origin rpy="0.0 ${-pi/2} 0.0" xyz="0.0 0.0 0.062"/>
      <axis xyz="0 -1 0"/>
    </joint>
    <link name="${prefix}flange">
    </link>
    <joint name="${prefix}flange_to_tool0" type="fixed">
      <parent link="${prefix}flange"/>
      <child link="${prefix}tool0"/>
      <origin rpy="0.0 0.0 0.0" xyz="0.0 0.0 0.0"/>
      <axis xyz="0 0 0"/>
    </joint>
    <link name="${prefix}tool0">
    </link>
  </xacro:macro>
</robot>
