<?xml version="1.0" ?>
<robot robot xmlns:xacro="https://wiki.ros.org/xacro"
       name="igus_robolink_rl_dp_5" >
  <link name="base_link">
    <visual>
      <geometry>
        <mesh filename="package://irc_ros_description/meshes/igus_robolink_rl_dp_5/Joint0.dae"/>
      </geometry>
    </visual>
    <collision>
      <geometry>
        <mesh filename="package://irc_ros_description/meshes/igus_robolink_rl_dp_5/Joint0Coll.dae"/>
      </geometry>
    </collision>
    <inertial>
      <mass value="1.0"/>
      <inertia ixx="1.0" ixy="0.0" ixz="0.0" iyy="1.0" iyz="0.0" izz="1.0"/>
    </inertial>
  </link>
  <joint name="joint1" type="revolute">
    <parent link="base_link"/>
    <child link="link_1"/>
    <origin rpy="0.0 0.0 0.0" xyz="0.0 0 0.0095"/>
    <axis xyz="0 0 -1"/>
    <limit effort="330.0" lower="${-pi*7/9}" upper="${pi*7/9}" velocity="2.16"/>
  </joint>
  <link name="link_1">
    <visual>
      <geometry>
        <mesh filename="package://irc_ros_description/meshes/igus_robolink_rl_dp_5/Joint1.dae"/>
      </geometry>
      <origin rpy="0 0 0" xyz="0 0 0"/>
    </visual>
    <collision>
      <geometry>
        <mesh filename="package://irc_ros_description/meshes/igus_robolink_rl_dp_5/Joint1Coll.dae"/>
      </geometry>
      <origin rpy="0 0 0" xyz="0 0 0"/>
    </collision>
    <inertial>
      <mass value="0.1"/>
      <inertia ixx="0.03" ixy="0.0" ixz="0.0" iyy="0.03" iyz="0.0" izz="0.03"/>
    </inertial>
  </link>
  <joint name="joint2" type="revolute">
    <parent link="link_1"/>
    <child link="link_2"/>
    <origin rpy="0.0 0.0 0.0" xyz="0.0 0 0.145"/>
    <axis xyz="0 1 0"/>
    <limit effort="330.0" lower="${-pi*5/18}" upper="${pi/2}" velocity="2.16"/>
  </joint>
  <link name="link_2">
    <visual>
      <geometry>
        <mesh filename="package://irc_ros_description/meshes/igus_robolink_rl_dp_5/Joint2.dae"/>
      </geometry>
      <origin rpy="0 0 0" xyz="0 0 0"/>
    </visual>
    <collision>
      <geometry>
        <mesh filename="package://irc_ros_description/meshes/igus_robolink_rl_dp_5/Joint2Coll.dae"/>
      </geometry>
      <origin rpy="0 0 0" xyz="0 0 0"/>
    </collision>
    <inertial>
      <mass value="0.1"/>
      <inertia ixx="0.03" ixy="0.0" ixz="0.0" iyy="0.03" iyz="0.0" izz="0.03"/>
    </inertial>
  </link>
  <joint name="joint3" type="revolute">
    <parent link="link_2"/>
    <child link="link_5"/>
    <origin rpy="0.0 1.57 0.0" xyz="0.0 0.0 0.350"/>
    <axis xyz="0 1 0"/>
    <limit effort="330.0" lower="${-pi*41/36}" upper="${pi*5/36}" velocity="2.16"/>
  </joint>
  <link name="link_5">
    <visual>
      <geometry>
        <mesh filename="package://irc_ros_description/meshes/igus_robolink_rl_dp_5/Joint3.dae"/>
      </geometry>
      <origin rpy="0 0 0" xyz="0 0 0"/>
    </visual>
    <collision>
      <geometry>
        <mesh filename="package://irc_ros_description/meshes/igus_robolink_rl_dp_5/Joint3Coll.dae"/>
      </geometry>
      <origin rpy="0 0 0" xyz="0 0 0"/>
    </collision>
    <inertial>
      <mass value="0.1"/>
      <inertia ixx="0.03" ixy="0.0" ixz="0.0" iyy="0.03" iyz="0.0" izz="0.03"/>
    </inertial>
  </link>
  <joint name="joint4" type="revolute">
    <parent link="link_5"/>
    <child link="link_6"/>
    <origin rpy="0.0 0.0 0.0" xyz="0.0 0 0.270"/>
    <axis xyz="0 1 0"/>
    <limit effort="330.0" lower="${-pi*5/9}" upper="${pi*5/9}" velocity="2.16"/>
  </joint>
  <link name="link_6">
    <visual>
      <geometry>
        <mesh filename="package://irc_ros_description/meshes/igus_robolink_rl_dp_5/Joint4.dae"/>
      </geometry>
      <origin rpy="0 0 0" xyz="0 0 0"/>
    </visual>
    <collision>
      <geometry>
        <mesh filename="package://irc_ros_description/meshes/igus_robolink_rl_dp_5/Joint4Coll.dae"/>
      </geometry>
      <origin rpy="0 0 0" xyz="0 0 0"/>
    </collision>
    <inertial>
      <mass value="0.1"/>
      <inertia ixx="0.03" ixy="0.0" ixz="0.0" iyy="0.03" iyz="0.0" izz="0.03"/>
    </inertial>
  </link>
  <xacro:if value="$(arg continuous_last_joint)">
    <joint name="joint5" type="continuous">
      <parent link="link_6"/>
      <child link="link_7"/>
      <origin rpy="0.0 0.0 0.0" xyz="0.0 0 0.1785"/>
      <axis xyz="0 0 1"/>
      <limit effort="330.0" velocity="2.16"/>
    </joint>
  </xacro:if>
  <xacro:unless value="$(arg continuous_last_joint)">
    <joint name="joint5" type="revolute">
      <parent link="link_6"/>
      <child link="link_7"/>
      <origin rpy="0.0 0.0 0.0" xyz="0.0 0 0.1785"/>
      <axis xyz="0 0 1"/>
      <limit effort="330.0" lower="${-pi*179/180}" upper="${pi*179/180}" velocity="2.16"/>
    </joint>
  </xacro:unless>
  <link name="link_7">
    <visual>
      <geometry>
        <mesh filename="package://irc_ros_description/meshes/igus_robolink_rl_dp_5/Joint5.dae"/>
      </geometry>
      <origin rpy="0 0 0" xyz="0 0 0"/>
    </visual>
    <collision>
      <geometry>
        <mesh filename="package://irc_ros_description/meshes/igus_robolink_rl_dp_5/Joint5Coll.dae"/>
      </geometry>
      <origin rpy="0 0 0" xyz="0 0 0"/>
    </collision>
    <inertial>
      <mass value="0.1"/>
      <inertia ixx="0.03" ixy="0.0" ixz="0.0" iyy="0.03" iyz="0.0" izz="0.03"/>
    </inertial>
  </link>
  <joint name="joint6" type="fixed">
    <parent link="link_7"/>
    <child link="hand"/>
    <origin rpy="0.0 0.0 0.0" xyz="0.0 0 0.0115"/>
    <axis xyz="0 0 1"/>
    <limit effort="330.0" lower="-1.65806" upper="1.65806" velocity="2.16"/>
  </joint>
  <link name="hand">
    <inertial>
      <mass value="0.1"/>
      <inertia ixx="0.03" ixy="0.0" ixz="0.0" iyy="0.03" iyz="0.0" izz="0.03"/>
    </inertial>
  </link>
</robot>
